Workbook
Name city: Transactions!$E:$E
Name net: Transactions!$O:$O
Name or: TransactionsTable500[Order ID]
Name order: Transactions!$A:$A
Name orders: Transactions!$A$130:$A$501
Name profit: Transactions!$Q:$Q
Name region: Transactions!$F:$F
Name Slicer_Category1: #N/A
Name Slicer_Country1: #N/A
Name Slicer_Customer_Type: #N/A
Name Slicer_Payment_Method1: #N/A
Name Slicer_Region: #N/A

Sheet Transactions
A1: Order ID | B1: Order Date | C1: month_order | D1: Store ID | E1: Country | F1: Region | G1: City | H1: Product | I1: Category | J1: Units Sold | K1: Unit Price | L1: Gross Sales | M1: Discount % | N1: Discount Amount | O1: Net Sales | P1: COGS | Q1: Profit | R1: Customer Type | S1: Payment Method | T1: Order Channel | U1: Customer Rating
A2: ORD500446 | B2: 2024-01-02 | C2: =TEXT(TransactionsTable500[[#This Row],[Order Date]],"mmm") -> Jan | D2: ST023 | E2: India | F2: Asia Pacific | G2: Bengaluru | H2: Frappe | I2: Cold Beverage | J2: 3 | K2: 4.97 | L2: 14.91 | M2: =TransactionsTable500[[#This Row],[Net Sales]]*10% -> 1.491 | N2: 0 | O2: 14.91 | P2: 6.21 | Q2: 8.7 | R2: Non-Member | S2: Credit Card | T2: In-Store | U2: 3
A3: ORD500267 | B3: 2024-01-02 | C3: =TEXT(TransactionsTable500[[#This Row],[Order Date]],"mmm") -> Jan | D3: ST028 | E3: UAE | F3: Middle East | G3: Dubai | H3: Frappe | I3: Cold Beverage | J3: 3 | K3: 5.21 | L3: 15.63 | M3: 0 | N3: 0 | O3: 15.63 | P3: 6.35 | Q3: 9.28 | R3: Non-Member | S3: Debit Card | T3: Mobile App | U3: 4
A4: ORD500430 | B4: 2024-01-04 | C4: =TEXT(TransactionsTable500[[#This Row],[Order Date]],"mmm") -> Jan | D4: ST029 | E4: UAE | F4: Middle East | G4: Dubai | H4: Frappe | I4: Cold Beverage | J4: 1 | K4: 4.95 | L4: 4.95 | M4: 0 | N4: 0 | O4: 4.95 | P4: 1.68 | Q4: 3.27 | R4: Non-Member | S4: Credit Card | T4: In-Store | U4: 1
A5: ORD500172 | B5: 2024-01-04 | C5: =TEXT(TransactionsTable500[[#This Row],[Order Date]],"mmm") -> Jan | D5: ST016 | E5: Germany | F5: Europe | G5: Munich | H5: Caesar Salad | I5: Food | J5: 1 | K5: 8.59 | L5: 8.59 | M5: 0.1 | N5: 0.86 | O5: 7.73 | P5: 3.07 | Q5: 4.66 | R5: Member | S5: Credit Card | T5: In-Store | U5: 4
A6: ORD500266 | B6: 2024-01-05 | C6: =TEXT(TransactionsTable500[[#This Row],[Order Date]],"mmm") -> Jan | D6: ST020 | E6: India | F6: Asia Pacific | G6: Mumbai | H6: Iced Tea | I6: Cold Beverage | J6: 2 | K6: 3.73 | L6: 7.46 | M6: 0.05 | N6: 0.37 | O6: 7.09 | P6: 2.46 | Q6: 4.63 | R6: Member | S6: Credit Card | T6: Mobile App | U6: 5
A7: ORD500397 | B7: 2024-01-05 | C7: =TEXT(TransactionsTable500[[#This Row],[Order Date]],"mmm") -> Jan | D7: ST018 | E7: Germany | F7: Europe | G7: Hamburg | H7: Ceramic Mug | I7: Merchandise | J7: 3 | K7: 9.39 | L7: 28.17 | M7: 0 | N7: 0 | O7: 28.17 | P7: 10.47 | Q7: 17.7 | R7: Non-Member | S7: Debit Card | T7: Mobile App | U7: 4
A8: ORD500199 | B8: 2024-01-05 | C8: =TEXT(TransactionsTable500[[#This Row],[Order Date]],"mmm") -> Jan | D8: ST002 | E8: USA | F8: North America | G8: New York | H8: Chocolate Chip Cookie | I8: Bakery | J8: 1 | K8: 2.58 | L8: 2.58 | M8: 0.05 | N8: 0.13 | O8: 2.45 | P8: 0.88 | Q8: 1.57 | R8: Non-Member | S8: Mobile Wallet | T8: In-Store | U8: 4 | W8: onkar | X8: =VLOOKUP(W8,TransactionsTable500[[#All],[Customer Type]:[Customer Rating]],4,) -> 4
A9: ORD500158 | B9: 2024-01-06 | C9: =TEXT(TransactionsTable500[[#This Row],[Order Date]],"mmm") -> Jan | D9: ST012 | E9: UK | F9: Europe | G9: Manchester | H9: Tumbler | I9: Merchandise | J9: 1 | K9: 14.53 | L9: 14.53 | M9: 0 | N9: 0 | O9: 14.53 | P9: 5.74 | Q9: 8.79 | R9: Member | S9: Credit Card | T9: Mobile App | U9: 4
A10: ORD500459 | B10: 2024-01-10 | C10: =TEXT(TransactionsTable500[[#This Row],[Order Date]],"mmm") -> Jan | D10: ST013 | E10: UK | F10: Europe | G10: Birmingham | H10: Avocado Toast | I10: Food | J10: 1 | K10: 6.67 | L10: 6.67 | M10: 0 | N10: 0 | O10: 6.67 | P10: 2.17 | Q10: 4.5 | R10: Member | S10: Debit Card | T10: Mobile App | U10: 4
A11: ORD500108 | B11: 2024-01-13 | C11: =TEXT(TransactionsTable500[[#This Row],[Order Date]],"mmm") -> Jan | D11: ST021 | E11: India | F11: Asia Pacific | G11: Delhi | H11: Iced Tea | I11: Cold Beverage | J11: 1 | K11: 3.88 | L11: 3.88 | M11: 0 | N11: 0 | O11: 3.88 | P11: 1.59 | Q11: 2.29 | R11: Non-Member | S11: Debit Card | T11: Mobile App | U11: 4
A12: ORD500129 | B12: 2024-01-14 | C12: =TEXT(TransactionsTable500[[#This Row],[Order Date]],"mmm") -> Jan | D12: ST007 | E12: USA | F12: North America | G12: Seattle | H12: Cold Brew | I12: Cold Beverage | J12: 1 | K12: 4.7 | L12: 4.7 | M12: 0 | N12: 0 | O12: 4.7 | P12: 1.63 | Q12: 3.07 | R12: Member | S12: Cash | T12: In-Store | U12: 2
A13: ORD500120 | B13: 2024-01-15 | C13: =TEXT(TransactionsTable500[[#This Row],[Order Date]],"mmm") -> Jan | D13: ST021 | E13: India | F13: Asia Pacific | G13: Delhi | H13: Ceramic Mug | I13: Merchandise | J13: 4 | K13: 8.87 | L13: 35.48 | M13: 0 | N13: 0 | O13: 35.48 | P13: 12.17 | Q13: 23.31 | R13: Non-Member | S13: Mobile Wallet | T13: Drive-Thru | U13: 3
A14: ORD500148 | B14: 2024-01-16 | C14: =TEXT(TransactionsTable500[[#This Row],[Order Date]],"mmm") -> Jan | D14: ST029 | E14: UAE | F14: Middle East | G14: Dubai | H14: Bagel with Cream Cheese | I14: Bakery | J14: 2 | K14: 3.52 | L14: 7.04 | M14: 0.05 | N14: 0.35 | O14: 6.69 | P14: 2.79 | Q14: 3.9 | R14: Member | S14: Credit Card | T14: Drive-Thru | U14: 4
A15: ORD500232 | B15: 2024-01-16 | C15: =TEXT(TransactionsTable500[[#This Row],[Order Date]],"mmm") -> Jan | D15: ST019 | E15: India | F15: Asia Pacific | G15: Mumbai | H15: Chocolate Chip Cookie | I15: Bakery | J15: 1 | K15: 2.57 | L15: 2.57 | M15: 0 | N15: 0 | O15: 2.57 | P15: 0.97 | Q15: 1.6 | R15: Corporate | S15: Mobile Wallet | T15: Mobile App | U15: 4
A16: ORD500363 | B16: 2024-01-17 | C16: =TEXT(TransactionsTable500[[#This Row],[Order Date]],"mmm") -> Jan | D16: ST012 | E16: UK | F16: Europe | G16: Manchester | H16: Latte | I16: Hot Beverage | J16: 1 | K16: 4.56 | L16: 4.56 | M16: 0 | N16: 0 | O16: 4.56 | P16: 1.54 | Q16: 3.02 | R16: Non-Member | S16: Credit Card | T16: Mobile App | U16: 4
A17: ORD500453 | B17: 2024-01-18 | C17: =TEXT(TransactionsTable500[[#This Row],[Order Date]],"mmm") -> Jan | D17: ST018 | E17: Germany | F17: Europe | G17: Hamburg | H17: Iced Latte | I17: Cold Beverage | J17: 1 | K17: 5.12 | L17: 5.12 | M17: 0 | N17: 0 | O17: 5.12 | P17: 1.88 | Q17: 3.24 | R17: Corporate | S17: Mobile Wallet | T17: Mobile App | U17: 4
A18: ORD500376 | B18: 2024-01-18 | C18: =TEXT(TransactionsTable500[[#This Row],[Order Date]],"mmm") -> Jan | D18: ST008 | E18: USA | F18: North America | G18: Seattle | H18: Espresso | I18: Hot Beverage | J18: 2 | K18: 3.6 | L18: 7.2 | M18: 0 | N18: 0 | O18: 7.2 | P18: 2.95 | Q18: 4.25 | R18: Non-Member | S18: Credit Card | T18: In-Store | U18: 3
A19: ORD500192 | B19: 2024-01-20 | C19: =TEXT(TransactionsTable500[[#This Row],[Order Date]],"mmm") -> Jan | D19: ST030 | E19: UAE | F19: Middle East | G19: Abu Dhabi | H19: Frappe | I19: Cold Beverage | J19: 1 | K19: 5.41 | L19: 5.41 | M19: 0 | N19: 0 | O19: 5.41 | P19: 2.08 | Q19: 3.33 | R19: Member | S19: Debit Card | T19: In-Store | U19: 5
A20: ORD500270 | B20: 2024-01-20 | C20: =TEXT(TransactionsTable500[[#This Row],[Order Date]],"mmm") -> Jan | D20: ST002 | E20: USA | F20: North America | G20: New York | H20: Americano | I20: Hot Beverage | J20: 2 | K20: 3.81 | L20: 7.62 | M20: 0.05 | N20: 0.38 | O20: 7.24 | P20: 2.52 | Q20: 4.72 | R20: Non-Member | S20: Mobile Wallet | T20: Drive-Thru | U20: 5
... A501: ORD500124 | B501: 2025-12-25 | C501: =TEXT(TransactionsTable500[[#This Row],[Order Date]],"mmm") -> Dec | D501: ST030 | E501: UAE | F501: Middle East | G501: Abu Dhabi | H501: Cold Brew | I501: Cold Beverage | J501: 2 | K501: 4.52 | L501: 9.04 | M501: 0 | N501: 0 | O501: 9.04 | P501: 3.76 | Q501: 5.28 | R501: Member | S501: Mobile Wallet | T501: In-Store | U501: 5

Sheet calculation
A1: card base KPIS
A2: total net sales | B2: =SUM(net) -> 5783.81
A3: Total Profit | B3: =SUM(Transactions!Q:Q) -> 3640.38
A4: Total Orders | B4: =COUNTA(or) -> 500
A5: Average Order Value | B5: =AVERAGE(net) -> 11.56762
A6: Average Customer Rating | B6: =AVERAGE(TransactionsTable500[Customer Rating]) -> 4.184
A8: chart base KPIs
A9: Monthly Net Sales
A10: Row Labels | B10: Sum of Net Sales
A11: Jan | B11: 443.3
A12: Feb | B12: 568.83
A13: Mar | B13: 510.94
A14: Apr | B14: 537.22
A15: May | B15: 459.76
A16: Jun | B16: 466.25
A17: Jul | B17: 461.87
A18: Aug | B18: 585.84
A19: Sep | B19: 334.94
A20: Oct | B20: 514.44
A21: Nov | B21: 580.32
A22: Dec | B22: 320.1
A23: Grand Total | B23: 5783.81
A25: profit by Category
A27: Row Labels | B27: Sum of Profit
A28: Bakery | B28: 371.95
A29: Cold Beverage | B29: 573.88
A30: Food | B30: 949.79
A31: Hot Beverage | B31: 527.45
A32: Merchandise | B32: 1217.31
A33: Grand Total | B33: 3640.38
A42: net sales by region
A44: Row Labels | B44: Sum of Net Sales
A45: Asia Pacific | B45: 1348.04
A46: Europe | B46: 1884.11
A47: Middle East | B47: 539.27
A48: North America | B48: 2012.39
A49: Grand Total | B49: 5783.81
A59: net sales by payment
A61: Row Labels | B61: Sum of Net Sales
A62: Cash | B62: 1073.3
...

Sheet Dashboard
E2: GLOBAL BREW DASHBOARD
C6: Total Net Sale | F6: Total Profit | I6: Total Orders | L6: Average Order Value | O6: Average Customer Rating
C7: 💰 | D7: =calculation!B2 -> 5783.81 | F7: 📈 | G7: =calculation!B3 -> 3640.38 | I7: 🛒 | J7: =calculation!B4 -> 500 | L7: 🧾 | M7: =calculation!B5 -> 11.56762 | O7: 📊 | P7: =calculation!B6 -> 4.184
F39: Country | G39: Net Sales | H39: Profit | I39: Orders | J39: Avg Rating
F40: Australia | G40: =SUMIF(TransactionsTable500[Country],"australia",TransactionsTable500[Net Sales]) -> 285.62 | H40: =SUMIF(city,"australia",TransactionsTable500[Profit]) -> 295.97 | I40: =COUNTIF(city,"australia") -> 32 | J40: =AVERAGEIF(city,"australia",TransactionsTable500[Customer Rating]) -> 4.28125
F41: Canada | G41: =SUMIF(TransactionsTable500[Country],"canada",TransactionsTable500[Net Sales]) -> 320.75 | H41: =SUMIF(city,"canada",TransactionsTable500[Profit]) -> 230.41 | I41: =COUNTIF(city,"canada") -> 31 | J41: =AVERAGEIF(city,"canada",TransactionsTable500[Customer Rating]) -> 4.1290323
F42: Germany | G42: =SUMIF(TransactionsTable500[Country],"germany",TransactionsTable500[Net Sales]) -> 733.66 | H42: =SUMIF(city,"germany",TransactionsTable500[Profit]) -> 589.77 | I42: =COUNTIF(city,"germany") -> 63 | J42: =AVERAGEIF(city,"germany",TransactionsTable500[Customer Rating]) -> 4.4285714
F43: India | G43: =SUMIF(TransactionsTable500[Country],"india",TransactionsTable500[Net Sales]) -> 1062.42 | H43: =SUMIF(city,"india",TransactionsTable500[Profit]) -> 576.11 | I43: =COUNTIF(city,"india") -> 94 | J43: =AVERAGEIF(city,"india",TransactionsTable500[Customer Rating]) -> 4.3085106
F44: UAE | G44: =SUMIF(TransactionsTable500[Country],"uae",TransactionsTable500[Net Sales]) -> 539.27 | H44: =SUMIF(city,"uae",TransactionsTable500[Profit]) -> 397.83 | I44: =COUNTIF(city,"uae") -> 51 | J44: =AVERAGEIF(city,"uae",TransactionsTable500[Customer Rating]) -> 3.96
F45: UK | G45: =SUMIF(TransactionsTable500[Country],"uk",TransactionsTable500[Net Sales]) -> 1150.45 | H45: =SUMIF(city,"uk",TransactionsTable500[Profit]) -> 622.41 | I45: =COUNTIF(city,"uk") -> 94 | J45: =AVERAGEIF(city,"uk",TransactionsTable500[Customer Rating]) -> 4.1382979
F46: USA | G46: =SUMIF(TransactionsTable500[Country],"usa",TransactionsTable500[Net Sales]) -> 1691.64 | H46: =SUMIF(city,"usa",TransactionsTable500[Profit]) -> 919.18 | I46: =COUNTIF(city,"usa") -> 135 | J46: =AVERAGEIF(city,"usa",TransactionsTable500[Customer Rating]) -> 4.0962963

Sheet Data Dictionary
A1: Column | B1: Description
A2: Order ID | B2: Unique transaction identifier
A3: Order Date | B3: Date the order was placed (2024-01-01 to 2025-12-31)
A4: Store ID | B4: Unique store identifier, links to Store Reference sheet
A5: Country | B5: Country where the store is located
A6: Region | B6: Business region grouping (North America, Europe, Asia Pacific, Middle East)
A7: City | B7: City where the store is located
A8: Product | B8: Item sold
A9: Category | B9: Product category: Hot Beverage, Cold Beverage, Bakery, Food, Merchandise
A10: Units Sold | B10: Quantity of the product sold in this transaction
A11: Unit Price | B11: Price per unit ($)
A12: Gross Sales | B12: Units Sold x Unit Price, before discount ($)
... A21: Customer Rating | B21: Customer satisfaction rating, 1 (low) to 5 (high)
